[2024-04-23 16:01:05,836][response.py:66][ERROR][140716655736576] - name 'NAT' is not defined
[2024-04-24 09:04:49,747][response.py:66][ERROR][139839277926144] - error: Failed to start domain. Domain50846bd8-2b2c-4dea-bc87-7e3900a00bd7state is error. 
[2024-04-24 09:30:27,282][response.py:66][ERROR][140095141422848] - error: Failed to start domain. Domain50846bd8-2b2c-4dea-bc87-7e3900a00bd7state is error. 
[2024-04-24 09:37:20,905][response.py:66][ERROR][140095141422848] - error: Failed to start domain. Domain50846bd8-2b2c-4dea-bc87-7e3900a00bd7state is error. 
[2024-04-24 09:40:38,960][response.py:66][ERROR][140095168173824] - error: Failed to start domain. Domain50846bd8-2b2c-4dea-bc87-7e3900a00bd7state is error. 
[2024-04-24 09:49:26,486][response.py:66][ERROR][140340942075648] - error: Failed to start domain. Domain50846bd8-2b2c-4dea-bc87-7e3900a00bd7state is error. 
[2024-04-24 09:49:43,428][response.py:66][ERROR][140340942075648] - error: Failed to start domain. Domain50846bd8-2b2c-4dea-bc87-7e3900a00bd7state is error. 
[2024-04-24 10:00:34,625][response.py:66][ERROR][139864142272256] - error: Failed to start domain. Domain50846bd8-2b2c-4dea-bc87-7e3900a00bd7state is error. 
[2024-04-24 10:25:53,322][response.py:66][ERROR][139870319433472] - error: Failed to start domain. Domain50846bd8-2b2c-4dea-bc87-7e3900a00bd7state is error. 
[2024-04-24 10:27:28,182][response.py:66][ERROR][139870089500416] - error: Failed to start domain. Domain50846bd8-2b2c-4dea-bc87-7e3900a00bd7state is error. 
[2024-04-24 10:28:59,360][response.py:66][ERROR][139870089500416] - The Volume is being used by the Guest with UUID 8083140c-b13c-45d5-8840-8a1defbc465c
[2024-04-24 10:28:59,361][app.py:828][ERROR][139870089500416] - Exception on /kvm/storage/delete [POST]
Traceback (most recent call last):
  File "/usr/local/lib/python3.8/dist-packages/flask/app.py", line 1463, in wsgi_app
    response = self.full_dispatch_request()
  File "/usr/local/lib/python3.8/dist-packages/flask/app.py", line 872, in full_dispatch_request
    rv = self.handle_user_exception(e)
  File "/usr/local/lib/python3.8/dist-packages/flask/app.py", line 870, in full_dispatch_request
    rv = self.dispatch_request()
  File "/usr/local/lib/python3.8/dist-packages/flask/app.py", line 855, in dispatch_request
    return self.ensure_sync(self.view_functions[rule.endpoint])(**view_args)  # type: ignore[no-any-return]
  File "/usr/local/lib/python3.8/dist-packages/flask_jwt_extended/view_decorators.py", line 170, in decorator
    return current_app.ensure_sync(fn)(*args, **kwargs)
  File "/home/york/VMManager/backend/src/utils/jwt.py", line 17, in wrapper
    res = func(*args, **kw)
  File "/home/york/VMManager/backend/src/blueprints/storage_bp.py", line 80, in delete_volume
    return storage_api.delete_volume(volmue_uuid).to_json_str()
  File "/home/york/VMManager/backend/src/utils/response.py", line 67, in to_json_str
    return json.dumps(self.__dict__)
  File "/usr/lib/python3.8/json/__init__.py", line 231, in dumps
    return _default_encoder.encode(obj)
  File "/usr/lib/python3.8/json/encoder.py", line 199, in encode
    chunks = self.iterencode(o, _one_shot=True)
  File "/usr/lib/python3.8/json/encoder.py", line 257, in iterencode
    return _iterencode(o, 0)
  File "/usr/lib/python3.8/json/encoder.py", line 179, in default
    raise TypeError(f'Object of type {o.__class__.__name__} '
TypeError: Object of type Exception is not JSON serializable
[2024-04-24 10:30:23,426][response.py:66][ERROR][139870089500416] - volume york1 deletion failed: rbd isn't exist.
[2024-04-24 10:30:23,426][app.py:828][ERROR][139870089500416] - Exception on /kvm/storage/delete [POST]
Traceback (most recent call last):
  File "/usr/local/lib/python3.8/dist-packages/flask/app.py", line 1463, in wsgi_app
    response = self.full_dispatch_request()
  File "/usr/local/lib/python3.8/dist-packages/flask/app.py", line 872, in full_dispatch_request
    rv = self.handle_user_exception(e)
  File "/usr/local/lib/python3.8/dist-packages/flask/app.py", line 870, in full_dispatch_request
    rv = self.dispatch_request()
  File "/usr/local/lib/python3.8/dist-packages/flask/app.py", line 855, in dispatch_request
    return self.ensure_sync(self.view_functions[rule.endpoint])(**view_args)  # type: ignore[no-any-return]
  File "/usr/local/lib/python3.8/dist-packages/flask_jwt_extended/view_decorators.py", line 170, in decorator
    return current_app.ensure_sync(fn)(*args, **kwargs)
  File "/home/york/VMManager/backend/src/utils/jwt.py", line 17, in wrapper
    res = func(*args, **kw)
  File "/home/york/VMManager/backend/src/blueprints/storage_bp.py", line 80, in delete_volume
    return storage_api.delete_volume(volmue_uuid).to_json_str()
  File "/home/york/VMManager/backend/src/utils/response.py", line 67, in to_json_str
    return json.dumps(self.__dict__)
  File "/usr/lib/python3.8/json/__init__.py", line 231, in dumps
    return _default_encoder.encode(obj)
  File "/usr/lib/python3.8/json/encoder.py", line 199, in encode
    chunks = self.iterencode(o, _one_shot=True)
  File "/usr/lib/python3.8/json/encoder.py", line 257, in iterencode
    return _iterencode(o, 0)
  File "/usr/lib/python3.8/json/encoder.py", line 179, in default
    raise TypeError(f'Object of type {o.__class__.__name__} '
TypeError: Object of type Exception is not JSON serializable
[2024-04-24 10:30:27,631][response.py:66][ERROR][139870089500416] - volume york2 deletion failed: rbd isn't exist.
[2024-04-24 10:30:27,631][app.py:828][ERROR][139870089500416] - Exception on /kvm/storage/delete [POST]
Traceback (most recent call last):
  File "/usr/local/lib/python3.8/dist-packages/flask/app.py", line 1463, in wsgi_app
    response = self.full_dispatch_request()
  File "/usr/local/lib/python3.8/dist-packages/flask/app.py", line 872, in full_dispatch_request
    rv = self.handle_user_exception(e)
  File "/usr/local/lib/python3.8/dist-packages/flask/app.py", line 870, in full_dispatch_request
    rv = self.dispatch_request()
  File "/usr/local/lib/python3.8/dist-packages/flask/app.py", line 855, in dispatch_request
    return self.ensure_sync(self.view_functions[rule.endpoint])(**view_args)  # type: ignore[no-any-return]
  File "/usr/local/lib/python3.8/dist-packages/flask_jwt_extended/view_decorators.py", line 170, in decorator
    return current_app.ensure_sync(fn)(*args, **kwargs)
  File "/home/york/VMManager/backend/src/utils/jwt.py", line 17, in wrapper
    res = func(*args, **kw)
  File "/home/york/VMManager/backend/src/blueprints/storage_bp.py", line 80, in delete_volume
    return storage_api.delete_volume(volmue_uuid).to_json_str()
  File "/home/york/VMManager/backend/src/utils/response.py", line 67, in to_json_str
    return json.dumps(self.__dict__)
  File "/usr/lib/python3.8/json/__init__.py", line 231, in dumps
    return _default_encoder.encode(obj)
  File "/usr/lib/python3.8/json/encoder.py", line 199, in encode
    chunks = self.iterencode(o, _one_shot=True)
  File "/usr/lib/python3.8/json/encoder.py", line 257, in iterencode
    return _iterencode(o, 0)
  File "/usr/lib/python3.8/json/encoder.py", line 179, in default
    raise TypeError(f'Object of type {o.__class__.__name__} '
TypeError: Object of type Exception is not JSON serializable
